2025-09-07 19:16:09.310 | INFO     | __main__:test_match_agent_azure:24 - üéØ Testing Match Finding Agent on Azure...
2025-09-07 19:16:09.310 | INFO     | __main__:test_match_agent_azure:47 - Sending request to Azure backend...
2025-09-07 19:16:09.982 | ERROR    | __main__:test_match_agent_azure:87 - ‚ùå Match finding test failed: [Errno -2] Name or service not known
2025-09-07 19:16:09.982 | ERROR    | __main__:test_match_agent_azure:88 - Full traceback:
2025-09-07 19:16:09.993 | ERROR    | __main__:test_match_agent_azure:89 - Traceback (most recent call last):
  File "/home/bilal/fyp_buddy/app/.venv/lib/python3.12/site-packages/httpx/_transports/default.py", line 101, in map_httpcore_exceptions
    yield
  File "/home/bilal/fyp_buddy/app/.venv/lib/python3.12/site-packages/httpx/_transports/default.py", line 394, in handle_async_request
    resp = await self._pool.handle_async_request(req)
           ^^^^^^^^^^^^^^^^^^^^^^^^^^^^^^^^^^^^^^^^^^
  File "/home/bilal/fyp_buddy/app/.venv/lib/python3.12/site-packages/httpcore/_async/connection_pool.py", line 256, in handle_async_request
    raise exc from None
  File "/home/bilal/fyp_buddy/app/.venv/lib/python3.12/site-packages/httpcore/_async/connection_pool.py", line 236, in handle_async_request
    response = await connection.handle_async_request(
               ^^^^^^^^^^^^^^^^^^^^^^^^^^^^^^^^^^^^^^
  File "/home/bilal/fyp_buddy/app/.venv/lib/python3.12/site-packages/httpcore/_async/connection.py", line 101, in handle_async_request
    raise exc
  File "/home/bilal/fyp_buddy/app/.venv/lib/python3.12/site-packages/httpcore/_async/connection.py", line 78, in handle_async_request
    stream = await self._connect(request)
             ^^^^^^^^^^^^^^^^^^^^^^^^^^^^
  File "/home/bilal/fyp_buddy/app/.venv/lib/python3.12/site-packages/httpcore/_async/connection.py", line 124, in _connect
    stream = await self._network_backend.connect_tcp(**kwargs)
             ^^^^^^^^^^^^^^^^^^^^^^^^^^^^^^^^^^^^^^^^^^^^^^^^^
  File "/home/bilal/fyp_buddy/app/.venv/lib/python3.12/site-packages/httpcore/_backends/auto.py", line 31, in connect_tcp
    return await self._backend.connect_tcp(
           ^^^^^^^^^^^^^^^^^^^^^^^^^^^^^^^^
  File "/home/bilal/fyp_buddy/app/.venv/lib/python3.12/site-packages/httpcore/_backends/anyio.py", line 113, in connect_tcp
    with map_exceptions(exc_map):
         ^^^^^^^^^^^^^^^^^^^^^^^
  File "/home/bilal/.local/share/uv/python/cpython-3.12.8-linux-x86_64-gnu/lib/python3.12/contextlib.py", line 158, in __exit__
    self.gen.throw(value)
  File "/home/bilal/fyp_buddy/app/.venv/lib/python3.12/site-packages/httpcore/_exceptions.py", line 14, in map_exceptions
    raise to_exc(exc) from exc
httpcore.ConnectError: [Errno -2] Name or service not known

The above exception was the direct cause of the following exception:

Traceback (most recent call last):
  File "/home/bilal/fyp_buddy/app/test_scripts/test_backend.py", line 49, in test_match_agent_azure
    response = await client.post(AZURE_BACKEND_URL, json=query_profile)
               ^^^^^^^^^^^^^^^^^^^^^^^^^^^^^^^^^^^^^^^^^^^^^^^^^^^^^^^^
  File "/home/bilal/fyp_buddy/app/.venv/lib/python3.12/site-packages/httpx/_client.py", line 1859, in post
    return await self.request(
           ^^^^^^^^^^^^^^^^^^^
  File "/home/bilal/fyp_buddy/app/.venv/lib/python3.12/site-packages/httpx/_client.py", line 1540, in request
    return await self.send(request, auth=auth, follow_redirects=follow_redirects)
           ^^^^^^^^^^^^^^^^^^^^^^^^^^^^^^^^^^^^^^^^^^^^^^^^^^^^^^^^^^^^^^^^^^^^^^
  File "/home/bilal/fyp_buddy/app/.venv/lib/python3.12/site-packages/httpx/_client.py", line 1629, in send
    response = await self._send_handling_auth(
               ^^^^^^^^^^^^^^^^^^^^^^^^^^^^^^^
  File "/home/bilal/fyp_buddy/app/.venv/lib/python3.12/site-packages/httpx/_client.py", line 1657, in _send_handling_auth
    response = await self._send_handling_redirects(
               ^^^^^^^^^^^^^^^^^^^^^^^^^^^^^^^^^^^^
  File "/home/bilal/fyp_buddy/app/.venv/lib/python3.12/site-packages/httpx/_client.py", line 1694, in _send_handling_redirects
    response = await self._send_single_request(request)
               ^^^^^^^^^^^^^^^^^^^^^^^^^^^^^^^^^^^^^^^^
  File "/home/bilal/fyp_buddy/app/.venv/lib/python3.12/site-packages/httpx/_client.py", line 1730, in _send_single_request
    response = await transport.handle_async_request(request)
               ^^^^^^^^^^^^^^^^^^^^^^^^^^^^^^^^^^^^^^^^^^^^^
  File "/home/bilal/fyp_buddy/app/.venv/lib/python3.12/site-packages/httpx/_transports/default.py", line 393, in handle_async_request
    with map_httpcore_exceptions():
         ^^^^^^^^^^^^^^^^^^^^^^^^^
  File "/home/bilal/.local/share/uv/python/cpython-3.12.8-linux-x86_64-gnu/lib/python3.12/contextlib.py", line 158, in __exit__
    self.gen.throw(value)
  File "/home/bilal/fyp_buddy/app/.venv/lib/python3.12/site-packages/httpx/_transports/default.py", line 118, in map_httpcore_exceptions
    raise mapped_exc(message) from exc
httpx.ConnectError: [Errno -2] Name or service not known

2025-09-07 19:17:21.902 | INFO     | __main__:test_match_agent_azure:24 - üéØ Testing Match Finding Agent on Azure...
2025-09-07 19:17:21.902 | INFO     | __main__:test_match_agent_azure:47 - Sending request to Azure backend...
2025-09-07 19:17:48.175 | ERROR    | __main__:test_match_agent_azure:87 - ‚ùå Match finding test failed: Backend returned status 405: {"detail":"Method Not Allowed"}
2025-09-07 19:17:48.176 | ERROR    | __main__:test_match_agent_azure:88 - Full traceback:
2025-09-07 19:17:48.178 | ERROR    | __main__:test_match_agent_azure:89 - Traceback (most recent call last):
  File "/home/bilal/fyp_buddy/app/test_scripts/test_backend.py", line 52, in test_match_agent_azure
    raise Exception(f"Backend returned status {response.status_code}: {response.text}")
Exception: Backend returned status 405: {"detail":"Method Not Allowed"}

2025-09-07 19:19:49.768 | INFO     | __main__:test_match_agent_azure:24 - üéØ Testing Match Finding Agent on Azure...
2025-09-07 19:19:49.769 | INFO     | __main__:test_match_agent_azure:47 - Sending request to Azure backend...
2025-09-07 19:20:50.703 | ERROR    | __main__:test_match_agent_azure:87 - ‚ùå Match finding test failed: 
2025-09-07 19:20:50.704 | ERROR    | __main__:test_match_agent_azure:88 - Full traceback:
2025-09-07 19:20:50.718 | ERROR    | __main__:test_match_agent_azure:89 - Traceback (most recent call last):
  File "/home/bilal/fyp_buddy/app/.venv/lib/python3.12/site-packages/httpx/_transports/default.py", line 101, in map_httpcore_exceptions
    yield
  File "/home/bilal/fyp_buddy/app/.venv/lib/python3.12/site-packages/httpx/_transports/default.py", line 394, in handle_async_request
    resp = await self._pool.handle_async_request(req)
           ^^^^^^^^^^^^^^^^^^^^^^^^^^^^^^^^^^^^^^^^^^
  File "/home/bilal/fyp_buddy/app/.venv/lib/python3.12/site-packages/httpcore/_async/connection_pool.py", line 256, in handle_async_request
    raise exc from None
  File "/home/bilal/fyp_buddy/app/.venv/lib/python3.12/site-packages/httpcore/_async/connection_pool.py", line 236, in handle_async_request
    response = await connection.handle_async_request(
               ^^^^^^^^^^^^^^^^^^^^^^^^^^^^^^^^^^^^^^
  File "/home/bilal/fyp_buddy/app/.venv/lib/python3.12/site-packages/httpcore/_async/connection.py", line 103, in handle_async_request
    return await self._connection.handle_async_request(request)
           ^^^^^^^^^^^^^^^^^^^^^^^^^^^^^^^^^^^^^^^^^^^^^^^^^^^^
  File "/home/bilal/fyp_buddy/app/.venv/lib/python3.12/site-packages/httpcore/_async/http11.py", line 136, in handle_async_request
    raise exc
  File "/home/bilal/fyp_buddy/app/.venv/lib/python3.12/site-packages/httpcore/_async/http11.py", line 106, in handle_async_request
    ) = await self._receive_response_headers(**kwargs)
        ^^^^^^^^^^^^^^^^^^^^^^^^^^^^^^^^^^^^^^^^^^^^^^
  File "/home/bilal/fyp_buddy/app/.venv/lib/python3.12/site-packages/httpcore/_async/http11.py", line 177, in _receive_response_headers
    event = await self._receive_event(timeout=timeout)
            ^^^^^^^^^^^^^^^^^^^^^^^^^^^^^^^^^^^^^^^^^^
  File "/home/bilal/fyp_buddy/app/.venv/lib/python3.12/site-packages/httpcore/_async/http11.py", line 217, in _receive_event
    data = await self._network_stream.read(
           ^^^^^^^^^^^^^^^^^^^^^^^^^^^^^^^^
  File "/home/bilal/fyp_buddy/app/.venv/lib/python3.12/site-packages/httpcore/_backends/anyio.py", line 32, in read
    with map_exceptions(exc_map):
         ^^^^^^^^^^^^^^^^^^^^^^^
  File "/home/bilal/.local/share/uv/python/cpython-3.12.8-linux-x86_64-gnu/lib/python3.12/contextlib.py", line 158, in __exit__
    self.gen.throw(value)
  File "/home/bilal/fyp_buddy/app/.venv/lib/python3.12/site-packages/httpcore/_exceptions.py", line 14, in map_exceptions
    raise to_exc(exc) from exc
httpcore.ReadTimeout

The above exception was the direct cause of the following exception:

Traceback (most recent call last):
  File "/home/bilal/fyp_buddy/app/test_scripts/test_backend.py", line 49, in test_match_agent_azure
    response = await client.post(AZURE_BACKEND_URL, json=query_profile)
               ^^^^^^^^^^^^^^^^^^^^^^^^^^^^^^^^^^^^^^^^^^^^^^^^^^^^^^^^
  File "/home/bilal/fyp_buddy/app/.venv/lib/python3.12/site-packages/httpx/_client.py", line 1859, in post
    return await self.request(
           ^^^^^^^^^^^^^^^^^^^
  File "/home/bilal/fyp_buddy/app/.venv/lib/python3.12/site-packages/httpx/_client.py", line 1540, in request
    return await self.send(request, auth=auth, follow_redirects=follow_redirects)
           ^^^^^^^^^^^^^^^^^^^^^^^^^^^^^^^^^^^^^^^^^^^^^^^^^^^^^^^^^^^^^^^^^^^^^^
  File "/home/bilal/fyp_buddy/app/.venv/lib/python3.12/site-packages/httpx/_client.py", line 1629, in send
    response = await self._send_handling_auth(
               ^^^^^^^^^^^^^^^^^^^^^^^^^^^^^^^
  File "/home/bilal/fyp_buddy/app/.venv/lib/python3.12/site-packages/httpx/_client.py", line 1657, in _send_handling_auth
    response = await self._send_handling_redirects(
               ^^^^^^^^^^^^^^^^^^^^^^^^^^^^^^^^^^^^
  File "/home/bilal/fyp_buddy/app/.venv/lib/python3.12/site-packages/httpx/_client.py", line 1694, in _send_handling_redirects
    response = await self._send_single_request(request)
               ^^^^^^^^^^^^^^^^^^^^^^^^^^^^^^^^^^^^^^^^
  File "/home/bilal/fyp_buddy/app/.venv/lib/python3.12/site-packages/httpx/_client.py", line 1730, in _send_single_request
    response = await transport.handle_async_request(request)
               ^^^^^^^^^^^^^^^^^^^^^^^^^^^^^^^^^^^^^^^^^^^^^
  File "/home/bilal/fyp_buddy/app/.venv/lib/python3.12/site-packages/httpx/_transports/default.py", line 393, in handle_async_request
    with map_httpcore_exceptions():
         ^^^^^^^^^^^^^^^^^^^^^^^^^
  File "/home/bilal/.local/share/uv/python/cpython-3.12.8-linux-x86_64-gnu/lib/python3.12/contextlib.py", line 158, in __exit__
    self.gen.throw(value)
  File "/home/bilal/fyp_buddy/app/.venv/lib/python3.12/site-packages/httpx/_transports/default.py", line 118, in map_httpcore_exceptions
    raise mapped_exc(message) from exc
httpx.ReadTimeout

2025-09-08 14:00:01.730 | INFO     | __main__:test_match_agent_azure:24 - üéØ Testing Match Finding Agent on Azure...
2025-09-08 14:00:01.730 | INFO     | __main__:test_match_agent_azure:47 - Sending request to Azure backend...
2025-09-08 14:01:02.299 | ERROR    | __main__:test_match_agent_azure:87 - ‚ùå Match finding test failed: 
2025-09-08 14:01:02.300 | ERROR    | __main__:test_match_agent_azure:88 - Full traceback:
2025-09-08 14:01:02.323 | ERROR    | __main__:test_match_agent_azure:89 - Traceback (most recent call last):
  File "/home/bilal/fyp_buddy/app/.venv/lib/python3.12/site-packages/httpx/_transports/default.py", line 101, in map_httpcore_exceptions
    yield
  File "/home/bilal/fyp_buddy/app/.venv/lib/python3.12/site-packages/httpx/_transports/default.py", line 394, in handle_async_request
    resp = await self._pool.handle_async_request(req)
           ^^^^^^^^^^^^^^^^^^^^^^^^^^^^^^^^^^^^^^^^^^
  File "/home/bilal/fyp_buddy/app/.venv/lib/python3.12/site-packages/httpcore/_async/connection_pool.py", line 256, in handle_async_request
    raise exc from None
  File "/home/bilal/fyp_buddy/app/.venv/lib/python3.12/site-packages/httpcore/_async/connection_pool.py", line 236, in handle_async_request
    response = await connection.handle_async_request(
               ^^^^^^^^^^^^^^^^^^^^^^^^^^^^^^^^^^^^^^
  File "/home/bilal/fyp_buddy/app/.venv/lib/python3.12/site-packages/httpcore/_async/connection.py", line 103, in handle_async_request
    return await self._connection.handle_async_request(request)
           ^^^^^^^^^^^^^^^^^^^^^^^^^^^^^^^^^^^^^^^^^^^^^^^^^^^^
  File "/home/bilal/fyp_buddy/app/.venv/lib/python3.12/site-packages/httpcore/_async/http11.py", line 136, in handle_async_request
    raise exc
  File "/home/bilal/fyp_buddy/app/.venv/lib/python3.12/site-packages/httpcore/_async/http11.py", line 106, in handle_async_request
    ) = await self._receive_response_headers(**kwargs)
        ^^^^^^^^^^^^^^^^^^^^^^^^^^^^^^^^^^^^^^^^^^^^^^
  File "/home/bilal/fyp_buddy/app/.venv/lib/python3.12/site-packages/httpcore/_async/http11.py", line 177, in _receive_response_headers
    event = await self._receive_event(timeout=timeout)
            ^^^^^^^^^^^^^^^^^^^^^^^^^^^^^^^^^^^^^^^^^^
  File "/home/bilal/fyp_buddy/app/.venv/lib/python3.12/site-packages/httpcore/_async/http11.py", line 217, in _receive_event
    data = await self._network_stream.read(
           ^^^^^^^^^^^^^^^^^^^^^^^^^^^^^^^^
  File "/home/bilal/fyp_buddy/app/.venv/lib/python3.12/site-packages/httpcore/_backends/anyio.py", line 32, in read
    with map_exceptions(exc_map):
         ^^^^^^^^^^^^^^^^^^^^^^^
  File "/home/bilal/.local/share/uv/python/cpython-3.12.8-linux-x86_64-gnu/lib/python3.12/contextlib.py", line 158, in __exit__
    self.gen.throw(value)
  File "/home/bilal/fyp_buddy/app/.venv/lib/python3.12/site-packages/httpcore/_exceptions.py", line 14, in map_exceptions
    raise to_exc(exc) from exc
httpcore.ReadTimeout

The above exception was the direct cause of the following exception:

Traceback (most recent call last):
  File "/home/bilal/fyp_buddy/app/test_scripts/test_backend.py", line 49, in test_match_agent_azure
    response = await client.post(AZURE_BACKEND_URL, json=query_profile)
               ^^^^^^^^^^^^^^^^^^^^^^^^^^^^^^^^^^^^^^^^^^^^^^^^^^^^^^^^
  File "/home/bilal/fyp_buddy/app/.venv/lib/python3.12/site-packages/httpx/_client.py", line 1859, in post
    return await self.request(
           ^^^^^^^^^^^^^^^^^^^
  File "/home/bilal/fyp_buddy/app/.venv/lib/python3.12/site-packages/httpx/_client.py", line 1540, in request
    return await self.send(request, auth=auth, follow_redirects=follow_redirects)
           ^^^^^^^^^^^^^^^^^^^^^^^^^^^^^^^^^^^^^^^^^^^^^^^^^^^^^^^^^^^^^^^^^^^^^^
  File "/home/bilal/fyp_buddy/app/.venv/lib/python3.12/site-packages/httpx/_client.py", line 1629, in send
    response = await self._send_handling_auth(
               ^^^^^^^^^^^^^^^^^^^^^^^^^^^^^^^
  File "/home/bilal/fyp_buddy/app/.venv/lib/python3.12/site-packages/httpx/_client.py", line 1657, in _send_handling_auth
    response = await self._send_handling_redirects(
               ^^^^^^^^^^^^^^^^^^^^^^^^^^^^^^^^^^^^
  File "/home/bilal/fyp_buddy/app/.venv/lib/python3.12/site-packages/httpx/_client.py", line 1694, in _send_handling_redirects
    response = await self._send_single_request(request)
               ^^^^^^^^^^^^^^^^^^^^^^^^^^^^^^^^^^^^^^^^
  File "/home/bilal/fyp_buddy/app/.venv/lib/python3.12/site-packages/httpx/_client.py", line 1730, in _send_single_request
    response = await transport.handle_async_request(request)
               ^^^^^^^^^^^^^^^^^^^^^^^^^^^^^^^^^^^^^^^^^^^^^
  File "/home/bilal/fyp_buddy/app/.venv/lib/python3.12/site-packages/httpx/_transports/default.py", line 393, in handle_async_request
    with map_httpcore_exceptions():
         ^^^^^^^^^^^^^^^^^^^^^^^^^
  File "/home/bilal/.local/share/uv/python/cpython-3.12.8-linux-x86_64-gnu/lib/python3.12/contextlib.py", line 158, in __exit__
    self.gen.throw(value)
  File "/home/bilal/fyp_buddy/app/.venv/lib/python3.12/site-packages/httpx/_transports/default.py", line 118, in map_httpcore_exceptions
    raise mapped_exc(message) from exc
httpx.ReadTimeout

2025-09-08 14:04:21.628 | INFO     | __main__:test_match_agent_azure:16 - üéØ Testing Match Finding Agent on Azure...
2025-09-08 14:04:21.723 | INFO     | __main__:test_match_agent_azure:40 - üì§ Sending request to /find_matches...
2025-09-08 14:05:22.464 | ERROR    | __main__:test_match_agent_azure:74 - ‚ùå Test failed: 
2025-09-08 14:05:22.477 | ERROR    | __main__:test_match_agent_azure:75 - Traceback (most recent call last):
  File "/home/bilal/fyp_buddy/app/.venv/lib/python3.12/site-packages/httpx/_transports/default.py", line 101, in map_httpcore_exceptions
    yield
  File "/home/bilal/fyp_buddy/app/.venv/lib/python3.12/site-packages/httpx/_transports/default.py", line 394, in handle_async_request
    resp = await self._pool.handle_async_request(req)
           ^^^^^^^^^^^^^^^^^^^^^^^^^^^^^^^^^^^^^^^^^^
  File "/home/bilal/fyp_buddy/app/.venv/lib/python3.12/site-packages/httpcore/_async/connection_pool.py", line 256, in handle_async_request
    raise exc from None
  File "/home/bilal/fyp_buddy/app/.venv/lib/python3.12/site-packages/httpcore/_async/connection_pool.py", line 236, in handle_async_request
    response = await connection.handle_async_request(
               ^^^^^^^^^^^^^^^^^^^^^^^^^^^^^^^^^^^^^^
  File "/home/bilal/fyp_buddy/app/.venv/lib/python3.12/site-packages/httpcore/_async/connection.py", line 103, in handle_async_request
    return await self._connection.handle_async_request(request)
           ^^^^^^^^^^^^^^^^^^^^^^^^^^^^^^^^^^^^^^^^^^^^^^^^^^^^
  File "/home/bilal/fyp_buddy/app/.venv/lib/python3.12/site-packages/httpcore/_async/http11.py", line 136, in handle_async_request
    raise exc
  File "/home/bilal/fyp_buddy/app/.venv/lib/python3.12/site-packages/httpcore/_async/http11.py", line 106, in handle_async_request
    ) = await self._receive_response_headers(**kwargs)
        ^^^^^^^^^^^^^^^^^^^^^^^^^^^^^^^^^^^^^^^^^^^^^^
  File "/home/bilal/fyp_buddy/app/.venv/lib/python3.12/site-packages/httpcore/_async/http11.py", line 177, in _receive_response_headers
    event = await self._receive_event(timeout=timeout)
            ^^^^^^^^^^^^^^^^^^^^^^^^^^^^^^^^^^^^^^^^^^
  File "/home/bilal/fyp_buddy/app/.venv/lib/python3.12/site-packages/httpcore/_async/http11.py", line 217, in _receive_event
    data = await self._network_stream.read(
           ^^^^^^^^^^^^^^^^^^^^^^^^^^^^^^^^
  File "/home/bilal/fyp_buddy/app/.venv/lib/python3.12/site-packages/httpcore/_backends/anyio.py", line 32, in read
    with map_exceptions(exc_map):
         ^^^^^^^^^^^^^^^^^^^^^^^
  File "/home/bilal/.local/share/uv/python/cpython-3.12.8-linux-x86_64-gnu/lib/python3.12/contextlib.py", line 158, in __exit__
    self.gen.throw(value)
  File "/home/bilal/fyp_buddy/app/.venv/lib/python3.12/site-packages/httpcore/_exceptions.py", line 14, in map_exceptions
    raise to_exc(exc) from exc
httpcore.ReadTimeout

The above exception was the direct cause of the following exception:

Traceback (most recent call last):
  File "/home/bilal/fyp_buddy/app/test_scripts/test_backend.py", line 41, in test_match_agent_azure
    response = await client.post(f"{AZURE_BACKEND_URL}/find_matches", json=query_profile)
               ^^^^^^^^^^^^^^^^^^^^^^^^^^^^^^^^^^^^^^^^^^^^^^^^^^^^^^^^^^^^^^^^^^^^^^^^^^
  File "/home/bilal/fyp_buddy/app/.venv/lib/python3.12/site-packages/httpx/_client.py", line 1859, in post
    return await self.request(
           ^^^^^^^^^^^^^^^^^^^
  File "/home/bilal/fyp_buddy/app/.venv/lib/python3.12/site-packages/httpx/_client.py", line 1540, in request
    return await self.send(request, auth=auth, follow_redirects=follow_redirects)
           ^^^^^^^^^^^^^^^^^^^^^^^^^^^^^^^^^^^^^^^^^^^^^^^^^^^^^^^^^^^^^^^^^^^^^^
  File "/home/bilal/fyp_buddy/app/.venv/lib/python3.12/site-packages/httpx/_client.py", line 1629, in send
    response = await self._send_handling_auth(
               ^^^^^^^^^^^^^^^^^^^^^^^^^^^^^^^
  File "/home/bilal/fyp_buddy/app/.venv/lib/python3.12/site-packages/httpx/_client.py", line 1657, in _send_handling_auth
    response = await self._send_handling_redirects(
               ^^^^^^^^^^^^^^^^^^^^^^^^^^^^^^^^^^^^
  File "/home/bilal/fyp_buddy/app/.venv/lib/python3.12/site-packages/httpx/_client.py", line 1694, in _send_handling_redirects
    response = await self._send_single_request(request)
               ^^^^^^^^^^^^^^^^^^^^^^^^^^^^^^^^^^^^^^^^
  File "/home/bilal/fyp_buddy/app/.venv/lib/python3.12/site-packages/httpx/_client.py", line 1730, in _send_single_request
    response = await transport.handle_async_request(request)
               ^^^^^^^^^^^^^^^^^^^^^^^^^^^^^^^^^^^^^^^^^^^^^
  File "/home/bilal/fyp_buddy/app/.venv/lib/python3.12/site-packages/httpx/_transports/default.py", line 393, in handle_async_request
    with map_httpcore_exceptions():
         ^^^^^^^^^^^^^^^^^^^^^^^^^
  File "/home/bilal/.local/share/uv/python/cpython-3.12.8-linux-x86_64-gnu/lib/python3.12/contextlib.py", line 158, in __exit__
    self.gen.throw(value)
  File "/home/bilal/fyp_buddy/app/.venv/lib/python3.12/site-packages/httpx/_transports/default.py", line 118, in map_httpcore_exceptions
    raise mapped_exc(message) from exc
httpx.ReadTimeout

2025-09-08 14:17:37.763 | INFO     | __main__:test_match_agent_azure:16 - üéØ Testing Match Finding Agent on Azure...
2025-09-08 14:17:37.844 | INFO     | __main__:test_match_agent_azure:40 - üì§ Sending request to /find_matches...
2025-09-08 14:18:38.486 | ERROR    | __main__:test_match_agent_azure:74 - ‚ùå Test failed: 
2025-09-08 14:18:38.500 | ERROR    | __main__:test_match_agent_azure:75 - Traceback (most recent call last):
  File "/home/bilal/fyp_buddy/app/.venv/lib/python3.12/site-packages/httpx/_transports/default.py", line 101, in map_httpcore_exceptions
    yield
  File "/home/bilal/fyp_buddy/app/.venv/lib/python3.12/site-packages/httpx/_transports/default.py", line 394, in handle_async_request
    resp = await self._pool.handle_async_request(req)
           ^^^^^^^^^^^^^^^^^^^^^^^^^^^^^^^^^^^^^^^^^^
  File "/home/bilal/fyp_buddy/app/.venv/lib/python3.12/site-packages/httpcore/_async/connection_pool.py", line 256, in handle_async_request
    raise exc from None
  File "/home/bilal/fyp_buddy/app/.venv/lib/python3.12/site-packages/httpcore/_async/connection_pool.py", line 236, in handle_async_request
    response = await connection.handle_async_request(
               ^^^^^^^^^^^^^^^^^^^^^^^^^^^^^^^^^^^^^^
  File "/home/bilal/fyp_buddy/app/.venv/lib/python3.12/site-packages/httpcore/_async/connection.py", line 103, in handle_async_request
    return await self._connection.handle_async_request(request)
           ^^^^^^^^^^^^^^^^^^^^^^^^^^^^^^^^^^^^^^^^^^^^^^^^^^^^
  File "/home/bilal/fyp_buddy/app/.venv/lib/python3.12/site-packages/httpcore/_async/http11.py", line 136, in handle_async_request
    raise exc
  File "/home/bilal/fyp_buddy/app/.venv/lib/python3.12/site-packages/httpcore/_async/http11.py", line 106, in handle_async_request
    ) = await self._receive_response_headers(**kwargs)
        ^^^^^^^^^^^^^^^^^^^^^^^^^^^^^^^^^^^^^^^^^^^^^^
  File "/home/bilal/fyp_buddy/app/.venv/lib/python3.12/site-packages/httpcore/_async/http11.py", line 177, in _receive_response_headers
    event = await self._receive_event(timeout=timeout)
            ^^^^^^^^^^^^^^^^^^^^^^^^^^^^^^^^^^^^^^^^^^
  File "/home/bilal/fyp_buddy/app/.venv/lib/python3.12/site-packages/httpcore/_async/http11.py", line 217, in _receive_event
    data = await self._network_stream.read(
           ^^^^^^^^^^^^^^^^^^^^^^^^^^^^^^^^
  File "/home/bilal/fyp_buddy/app/.venv/lib/python3.12/site-packages/httpcore/_backends/anyio.py", line 32, in read
    with map_exceptions(exc_map):
         ^^^^^^^^^^^^^^^^^^^^^^^
  File "/home/bilal/.local/share/uv/python/cpython-3.12.8-linux-x86_64-gnu/lib/python3.12/contextlib.py", line 158, in __exit__
    self.gen.throw(value)
  File "/home/bilal/fyp_buddy/app/.venv/lib/python3.12/site-packages/httpcore/_exceptions.py", line 14, in map_exceptions
    raise to_exc(exc) from exc
httpcore.ReadTimeout

The above exception was the direct cause of the following exception:

Traceback (most recent call last):
  File "/home/bilal/fyp_buddy/app/test_scripts/test_backend.py", line 41, in test_match_agent_azure
    response = await client.post(f"{AZURE_BACKEND_URL}/find_matches", json=query_profile)
               ^^^^^^^^^^^^^^^^^^^^^^^^^^^^^^^^^^^^^^^^^^^^^^^^^^^^^^^^^^^^^^^^^^^^^^^^^^
  File "/home/bilal/fyp_buddy/app/.venv/lib/python3.12/site-packages/httpx/_client.py", line 1859, in post
    return await self.request(
           ^^^^^^^^^^^^^^^^^^^
  File "/home/bilal/fyp_buddy/app/.venv/lib/python3.12/site-packages/httpx/_client.py", line 1540, in request
    return await self.send(request, auth=auth, follow_redirects=follow_redirects)
           ^^^^^^^^^^^^^^^^^^^^^^^^^^^^^^^^^^^^^^^^^^^^^^^^^^^^^^^^^^^^^^^^^^^^^^
  File "/home/bilal/fyp_buddy/app/.venv/lib/python3.12/site-packages/httpx/_client.py", line 1629, in send
    response = await self._send_handling_auth(
               ^^^^^^^^^^^^^^^^^^^^^^^^^^^^^^^
  File "/home/bilal/fyp_buddy/app/.venv/lib/python3.12/site-packages/httpx/_client.py", line 1657, in _send_handling_auth
    response = await self._send_handling_redirects(
               ^^^^^^^^^^^^^^^^^^^^^^^^^^^^^^^^^^^^
  File "/home/bilal/fyp_buddy/app/.venv/lib/python3.12/site-packages/httpx/_client.py", line 1694, in _send_handling_redirects
    response = await self._send_single_request(request)
               ^^^^^^^^^^^^^^^^^^^^^^^^^^^^^^^^^^^^^^^^
  File "/home/bilal/fyp_buddy/app/.venv/lib/python3.12/site-packages/httpx/_client.py", line 1730, in _send_single_request
    response = await transport.handle_async_request(request)
               ^^^^^^^^^^^^^^^^^^^^^^^^^^^^^^^^^^^^^^^^^^^^^
  File "/home/bilal/fyp_buddy/app/.venv/lib/python3.12/site-packages/httpx/_transports/default.py", line 393, in handle_async_request
    with map_httpcore_exceptions():
         ^^^^^^^^^^^^^^^^^^^^^^^^^
  File "/home/bilal/.local/share/uv/python/cpython-3.12.8-linux-x86_64-gnu/lib/python3.12/contextlib.py", line 158, in __exit__
    self.gen.throw(value)
  File "/home/bilal/fyp_buddy/app/.venv/lib/python3.12/site-packages/httpx/_transports/default.py", line 118, in map_httpcore_exceptions
    raise mapped_exc(message) from exc
httpx.ReadTimeout

